# 에러 처리

## 에러 처리의 필요성

발생한 에러에 대해 대처하지 않고 방치하면 프로그램은 강제 종료됨

`try...catch` 문을 사용해 발생한 에러에 적절하게 대응하면\
프로그램이 강제 종료되지 않고 계속해서 코드를 실행시킬 수 있음

직접적으로 에러를 발생하지 않은 예외적인 상황이 발생할 수도 있음

`querySelector` 메서드는 인수로 전달한 문자열이 CSS 선택자 문법에 맞지 않는 경우 에러를 발생시킴

하지만 `querySelector` 메서드는 인수로 전달한 CSS 선택자 문자열로 DOM에서 요소 노드를 찾을 수 없는 경우\
에러를 발생시키지 않고 `null`을 반환함\
이때 `if` 문으로 `querySelector` 메서드의 반환값을 확인하거나 단축 평가 또는 옵셔널 체이닝 연산자 `?.`를\
사용하지 않으면 다음 처리에서 에러로 이어질 가능성이 큼

```jsx
// DOM에 button 요소가 존재하는 경우 querySelector 메서드는 에러를 발생시키지 않고 null을 반환
const $button = document.querySelector('button');
$button?.classList.add('disabled');
```

## try...catch...finally 문

일반적으로 에러 처리(error handling)라고 함\
`finally` 문은 불필요하다면 생략 가능\
`catch` 문도 생략 가능하지만 `catch` 문이 없는 `try` 문은 의미가 없으므로 생략하지 않음

```jsx
try {
  // 실행할 코드(에러가 발생할 가능성이 있는 코드)
} catch (err) {
  // try 코드 블록에서 에러가 발생하면 이 코드 블록의 코드가 실행
  // err에는 try 코드 블록에서 발생한 Error 객체가 전달
} finally {
  // 에러 발생과 상관없이 반드시 한 번 실행
}
```

## Error 객체

`Error` 생성자 함수는 에러 객체를 생성함\
`Error` 생성자 함수에는 에러를 상세히 설명하는 에러 메시지를 인수로 전달할 수 있음

```jsx
const error = new Error('invalid');
```

`Error` 생성자 함수가 생성한 에러 객체는 `message` 프로퍼티와 `stack` 프로퍼티를 가짐\
`message` 프로퍼티의 값은 `Error` 생성자 함수에 인수로 전달한 에러 메시지고,\
`stack` 프로퍼티의 값은 에러를 발생시킨 콜 스택의 호출 정보를 나타내는 문자열이며 디버깅 목적으로 사용함

`SyntaxError`, `ReferenceError`, `TypeError`, `RangeError`, `URIError`, `EvalError` 생성자 함수가\
생성한 에러 객체의 프로토타입은 모두 `Error.prototype`을 상속받음

자바스크립트에서 제공하는 에러 객체를 생성할 수 있는 `Error` 생성자 함수

| 생성자 함수      | 인스턴스                                                                           |
| ---------------- | ---------------------------------------------------------------------------------- |
| `Error`          | 일반적 에러 객체                                                                   |
| `SyntaxError`    | 자바스크립트 문법에 맞지 않는 문을 해석할 때 발생하는 에러 객체                    |
| `ReferenceError` | 참조할 수 없는 식별자를 참조했을 때 발생하는 에러 객체                             |
| `TypeError`      | 피연산자 또는 인수의 데이터 타입이 유효하지 않을 때 발생하는 에러 객체             |
| `RangeError`     | 숫자값의 허용 범위를 벗어났을 때 발생하는 에러 객체                                |
| `URIError`       | `encodeURI` 또는 `decodeURI` 함수에 부적절한 인수를 전달했을 때 발생하는 에러 객체 |
| `EvalError`      | `eval` 함수에서 발생하는 에러 객체                                                 |

## throw문

`Error` 생성자 함수로 에러 객체를 생성한다고 에러가 발생하는 것은 아님

에러를 발생시키려면 `try` 코드 블록에서 `throw` 문으로 에러 객체를 던져야 함

`throw` 문의 표현식은 어떤 값이라도 상관없지만 일반적으로 에러 객체를 지정함\
에러를 던지면 `catch` 문의 에러 변수가 생성되고 던져진 에러 객체가 할당됨

```jsx
try {
  // 에러 객체를 던지면 catch 코드 블록이 실행되기 시작
  throw new Error('someting wrong');
} catch (error) {
  console.log(error);
}
```

## 에러의 전파

```jsx
const foo = () => {
  throw Error('foo에서 발생한 에러'); // 4
};

const bar = () => {
  foo(); // 3
};

const baz = () => {
  bar(); // 2
};

try {
  baz(); // 1
} catch (err) {
  console.error(err);
}
```

1에서 `baz` 함수를 호출하면 2에서 `bar` 함수가 호출되고\
3에서 `foo` 함수가 호출되고 `foo` 함수는 4에서 에러를 `throw`함\
이때 `foo` 함수가 `throw`한 에러는 호출자 방향으로 전파되어 전역에서 캐치됨

`throw`된 에러를 캐치하지 않으면 호출자 방향으로 전파됨\
이때 `throw`된 에러를 캐치하여 적절히 대응하면 프로그램을 강제 종료시키지 않고 코드의 실행 흐름을 복구할 수 있음\
`throw`된 에러를 어디에서도 캐치하지 않으면 프로그램은 강제 종료됨

주의할 것은 비동기 함수인 `setTimeout`이나 프로미스 후속 처리 메서드의 콜백 함수는 호출자가 없다는 것\
따라서 에러를 전파할 호출자가 존재하지 않음
